[2021-12-28 02:40:00,619] {taskinstance.py:851} INFO - Dependencies all met for <TaskInstance: data_transform.connect_minio 2021-12-28T02:39:52.730982+00:00 [queued]>
[2021-12-28 02:40:00,634] {taskinstance.py:851} INFO - Dependencies all met for <TaskInstance: data_transform.connect_minio 2021-12-28T02:39:52.730982+00:00 [queued]>
[2021-12-28 02:40:00,635] {taskinstance.py:1042} INFO - 
--------------------------------------------------------------------------------
[2021-12-28 02:40:00,635] {taskinstance.py:1043} INFO - Starting attempt 1 of 1
[2021-12-28 02:40:00,636] {taskinstance.py:1044} INFO - 
--------------------------------------------------------------------------------
[2021-12-28 02:40:00,644] {taskinstance.py:1063} INFO - Executing <Task(PythonOperator): connect_minio> on 2021-12-28T02:39:52.730982+00:00
[2021-12-28 02:40:00,649] {standard_task_runner.py:52} INFO - Started process 64 to run task
[2021-12-28 02:40:00,654] {standard_task_runner.py:76} INFO - Running: ['airflow', 'tasks', 'run', 'data_transform', 'connect_minio', '2021-12-28T02:39:52.730982+00:00', '--job-id', '58', '--pool', 'default_pool', '--raw', '--subdir', 'DAGS_FOLDER/data_transform.py', '--cfg-path', '/tmp/tmpr6h3e3ww', '--error-file', '/tmp/tmp5f878g_l']
[2021-12-28 02:40:00,654] {standard_task_runner.py:77} INFO - Job 58: Subtask connect_minio
[2021-12-28 02:40:00,699] {logging_mixin.py:104} INFO - Running <TaskInstance: data_transform.connect_minio 2021-12-28T02:39:52.730982+00:00 [running]> on host 5bb2b5ffa55c
[2021-12-28 02:40:00,739] {taskinstance.py:1257} INFO - Exporting the following env vars:
AIRFLOW_CTX_DAG_OWNER=airflow
AIRFLOW_CTX_DAG_ID=data_transform
AIRFLOW_CTX_TASK_ID=connect_minio
AIRFLOW_CTX_EXECUTION_DATE=2021-12-28T02:39:52.730982+00:00
AIRFLOW_CTX_DAG_RUN_ID=manual__2021-12-28T02:39:52.730982+00:00
[2021-12-28 02:40:00,804] {taskinstance.py:1455} ERROR - 'Date'
Traceback (most recent call last):
  File "/home/airflow/.local/lib/python3.6/site-packages/pandas/core/indexes/base.py", line 2898, in get_loc
    return self._engine.get_loc(casted_key)
  File "pandas/_libs/index.pyx", line 70, in pandas._libs.index.IndexEngine.get_loc
  File "pandas/_libs/index.pyx", line 101, in pandas._libs.index.IndexEngine.get_loc
  File "pandas/_libs/hashtable_class_helper.pxi", line 1675, in pandas._libs.hashtable.PyObjectHashTable.get_item
  File "pandas/_libs/hashtable_class_helper.pxi", line 1683, in pandas._libs.hashtable.PyObjectHashTable.get_item
KeyError: 'Date'

The above exception was the direct cause of the following exception:

Traceback (most recent call last):
  File "/home/airflow/.local/lib/python3.6/site-packages/airflow/models/taskinstance.py", line 1112, in _run_raw_task
    self._prepare_and_execute_task_with_callbacks(context, task)
  File "/home/airflow/.local/lib/python3.6/site-packages/airflow/models/taskinstance.py", line 1285, in _prepare_and_execute_task_with_callbacks
    result = self._execute_task(context, task_copy)
  File "/home/airflow/.local/lib/python3.6/site-packages/airflow/models/taskinstance.py", line 1315, in _execute_task
    result = task_copy.execute(context=context)
  File "/home/airflow/.local/lib/python3.6/site-packages/airflow/operators/python.py", line 117, in execute
    return_value = self.execute_callable()
  File "/home/airflow/.local/lib/python3.6/site-packages/airflow/operators/python.py", line 128, in execute_callable
    return self.python_callable(*self.op_args, **self.op_kwargs)
  File "/opt/airflow/dags/data_transform.py", line 193, in connect_minio
    for i in range(0,len(df_new2["Date"])):
  File "/home/airflow/.local/lib/python3.6/site-packages/pandas/core/frame.py", line 2906, in __getitem__
    indexer = self.columns.get_loc(key)
  File "/home/airflow/.local/lib/python3.6/site-packages/pandas/core/indexes/base.py", line 2900, in get_loc
    raise KeyError(key) from err
KeyError: 'Date'
[2021-12-28 02:40:00,814] {taskinstance.py:1503} INFO - Marking task as FAILED. dag_id=data_transform, task_id=connect_minio, execution_date=20211228T023952, start_date=20211228T024000, end_date=20211228T024000
[2021-12-28 02:40:00,864] {local_task_job.py:146} INFO - Task exited with return code 1
